<?xml version="1.0" ?>
<!-- =================================================================================== -->
<!-- |    This document was autogenerated by xacro from /home/vaspan/code/ws_moveit/src/fullbot/urdf/fullbot.urdf.xacro | -->
<!-- |    EDITING THIS FILE BY HAND IS NOT RECOMMENDED                                 | -->
<!-- =================================================================================== -->
<!-- This URDF was automatically created by SolidWorks to URDF Exporter! Originally created by Stephen Brawner (brawner@gmail.com) 
     Commit Version: 1.6.0-4-g7f85cfe  Build Version: 1.6.7995.38578
     For more information, please see http://wiki.ros.org/sw_urdf_exporter -->
<robot name="fullbot">
    <!-- Specify some standard inertial calculations https://en.wikipedia.org/wiki/List_of_moments_of_inertia -->
    <!-- These make use of xacro's mathematical functionality -->
    <material name="white">
        <color rgba="1 1 1 1" />
    </material>
    <material name="orange">
        <color rgba="1 0.3 0.1 1" />
    </material>
    <material name="blue">
        <color rgba="0.2 0.2 1 1" />
    </material>
    <material name="black">
        <color rgba="0 0 0 1" />
    </material>
  <gazebo>
    <plugin name="gazebo_ros_control" filename="libgazebo_ros_control.so">
      <robotNamespace>/</robotNamespace>
      <robotSimType>gazebo_ros_control/DefaultRobotHWSim</robotSimType>
    </plugin>
    <plugin name="dipole_magnet" filename="libfullbot_plugin.so">
    </plugin>
    <!-- <plugin name="dipole_magnet" filename="libstorm_gazebo_ros_magnet.so">
        <bodyName>link6_left</bodyName>
        <dipole_moment>0 0 80</dipole_moment>
        <shouldPublish>true</shouldPublish>
        <topicNs>capsule</topicNs>
        <updateRate>0</updateRate>
    </plugin> -->
    <!-- <plugin name="fullbot_wheel_controller" filename="libgazebo_ros_planar_move.so">
      <commandTopic>cmd_vel</commandTopic>
      <odometryTopic>odom</odometryTopic>
      <odometryFrame>odom</odometryFrame>
      <odometryRate>30.0</odometryRate>
      <robotBaseFrame>chassis</robotBaseFrame>
    </plugin> -->
  </gazebo>
  
  <link
    name="base_link">
    <inertial>
      <origin
        xyz="-0.00237670668945162 0.00109688224125671 0.762061321867194"
        rpy="0 0 0" />
      <mass
        value="83.9918863501521" />
      <inertia
        ixx="4.58131435742131"
        ixy="-3.09418403263941E-10"
        ixz="0.000336204370522542"
        iyy="3.15330051931996"
        iyz="-7.78528789321876E-10"
        izz="3.71265295574349" />
    </inertial>
    <visual>
      <origin
        xyz="0 0 0"
        rpy="0 0 0" />
      <geometry>
        <mesh
          filename="package://fullbot/meshes/base_link.STL" />
      </geometry>
      <material
        name="">
        <color
          rgba="0.752941176470588 0.752941176470588 0.752941176470588 1" />
      </material>
    </visual>
    <collision>
      <origin
        xyz="0 0 0"
        rpy="0 0 0" />
      <geometry>
        <mesh
          filename="package://fullbot/meshes/base_link.STL" />
      </geometry>
        <surface>
            <friction>
                <ode>
                    <mu>0.0</mu>
                    <mu2>0.0</mu2>
                    <fdir1>0.000000 0.000000 0.000000</fdir1>
                    <slip1>0.000000</slip1>
                    <slip2>0.000000</slip2>
                </ode>
            </friction>
        </surface>
    </collision>
  </link>
    <link name="link0_up">
        <inertial>
            <origin rpy="0 0 0" xyz="0.0015235 -9.2098E-05 0.072171" />
            <mass value="1.1501" />
            <inertia ixx="0.003053" ixy="7.4972E-06" ixz="7.8812E-05" iyy="0.003154" iyz="-4.773E-06" izz="0.001496" />
        </inertial>
        <visual>
            <origin rpy="0 0 0" xyz="0 0 0" />
            <geometry>
                <mesh filename="package://fullbot/meshes/link0_up.STL" />
            </geometry>
            <material name="">
                <color rgba="0.79216 0.81961 0.93333 1" />
            </material>
        </visual>
        <collision>
            <origin rpy="0 0 0" xyz="0 0 0" />
            <geometry>
                <mesh filename="package://fullbot/meshes/link0_up.STL" />
            </geometry>
        </collision>
    </link>
    <joint name="joint0_up" type="fixed">
        <origin rpy="0 0 -1.5708" xyz="0 0 1.2629" />
        <parent link="base_link" />
        <child link="link0_up" />
        <axis xyz="0 0 0" />
    </joint>
    <link name="link1_up">
        <inertial>
            <origin rpy="0 0 0" xyz="-0.0063511653118558 0.000207381647010473 0.0933560245185359" />
            <mass value="1.3256364074878" />
            <inertia ixx="0.00337516344067471" ixy="2.91047495398255E-06" ixz="0.000390263321422471" iyy="0.0039707875530841" iyz="-7.74618991821578E-06" izz="0.00211705553045749" />
        </inertial>
        <visual>
            <origin rpy="0 0 0" xyz="0 0 0" />
            <geometry>
                <mesh filename="package://fullbot/meshes/link1_up.STL" />
            </geometry>
            <material name="">
                <color rgba="0.792156862745098 0.819607843137255 0.933333333333333 1" />
            </material>
        </visual>
        <collision>
            <origin rpy="0 0 0" xyz="0 0 0" />
            <geometry>
                <mesh filename="package://fullbot/meshes/link1_up.STL" />
            </geometry>
        </collision>
    </link>
    <joint name="joint1_up" type="revolute">
        <origin rpy="0 0 0" xyz="0 0 0.1448" />
        <parent link="link0_up" />
        <child link="link1_up" />
        <axis xyz="0 0 1" />
        <limit effort="20" lower="-6.28" upper="6.28" velocity="1.5" />
    </joint>
    <link name="link2_up">
        <inertial>
            <origin rpy="0 0 0" xyz="-0.164334922175456 -0.0131391380189071 -0.0386527377791693" />
            <mass value="2.69348731441247" />
            <inertia ixx="0.00426310623774934" ixy="-0.00277535500543395" ixz="-0.000798338261530704" iyy="0.0150045970572789" iyz="0.000100430735697421" izz="0.0156052703291197" />
        </inertial>
        <visual>
            <origin rpy="0 0 0" xyz="0 0 0" />
            <geometry>
                <mesh filename="package://fullbot/meshes/link2_up.STL" />
            </geometry>
            <material name="">
                <color rgba="0.792156862745098 0.819607843137255 0.933333333333333 1" />
            </material>
        </visual>
        <collision>
            <origin rpy="0 0 0" xyz="0 0 0" />
            <geometry>
                <mesh filename="package://fullbot/meshes/link2_up.STL" />
            </geometry>
        </collision>
    </link>
    <joint name="joint2_up" type="revolute">
        <origin rpy="3.1416 1.5708 0" xyz="-0.065295 0.00034902 0.122" />
        <parent link="link1_up" />
        <child link="link2_up" />
        <axis xyz="0 0 1" />
        <limit effort="20" lower="-2.05" upper="2.09" velocity="1.5" />
    </joint>
    <link name="link3_up">
        <inertial>
            <origin rpy="0 0 0" xyz="0.0790017026576337 -0.0622013013556818 -0.0189186889395293" />
            <mass value="1.30253510106472" />
            <inertia ixx="0.00393747848651755" ixy="0.00136510222638933" ixz="0.00159608028913008" iyy="0.00525344165407256" iyz="-0.000920518752882782" izz="0.00455361194720345" />
        </inertial>
        <visual>
            <origin rpy="0 0 0" xyz="0 0 0" />
            <geometry>
                <mesh filename="package://fullbot/meshes/link3_up.STL" />
            </geometry>
            <material name="">
                <color rgba="0.792156862745098 0.819607843137255 0.933333333333333 1" />
            </material>
        </visual>
        <collision>
            <origin rpy="0 0 0" xyz="0 0 0" />
            <geometry>
                <mesh filename="package://fullbot/meshes/link3_up.STL" />
            </geometry>
        </collision>
    </link>
    <joint name="joint3_up" type="revolute">
        <origin rpy="0 0 0" xyz="-0.2859 -0.053313 -0.0083026" />
        <parent link="link2_up" />
        <child link="link3_up" />
        <axis xyz="0 0 1" />
        <limit effort="20" lower="-3.92" upper="0.19" velocity="1.5" />
    </joint>
    <link name="link4_up">
        <inertial>
            <origin rpy="0 0 0" xyz="0.0321807687354634 -0.00025917554824062 0.107627187331175" />
            <mass value="0.789560351493029" />
            <inertia ixx="0.00404949168648296" ixy="-3.36598707087041E-06" ixz="-0.00099079876639351" iyy="0.00449572325717299" iyz="-2.2965154074987E-06" izz="0.00105175547833875" />
        </inertial>
        <visual>
            <origin rpy="0 0 0" xyz="0 0 0" />
            <geometry>
                <mesh filename="package://fullbot/meshes/link4_up.STL" />
            </geometry>
            <material name="">
                <color rgba="0.792156862745098 0.819607843137255 0.933333333333333 1" />
            </material>
        </visual>
        <collision>
            <origin rpy="0 0 0" xyz="0 0 0" />
            <geometry>
                <mesh filename="package://fullbot/meshes/link4_up.STL" />
            </geometry>
        </collision>
    </link>
    <joint name="joint4_up" type="revolute">
        <origin rpy="0 1.5708 0" xyz="0.15917 -0.077751 -0.057495" />
        <parent link="link3_up" />
        <child link="link4_up" />
        <axis xyz="0 0 1" />
        <limit effort="20" lower="-6.28" upper="6.28" velocity="1.5" />
    </joint>
    <link name="link5_up">
        <inertial>
            <origin rpy="0 0 0" xyz="0.0467464429721704 -0.00940639676845523 -0.0231013060407902" />
            <mass value="0.723051769580643" />
            <inertia ixx="0.000793027726972335" ixy="0.000197964210793357" ixz="-0.000254464226983087" iyy="0.00148592083068407" iyz="5.97819367646225E-05" izz="0.00164704279225573" />
        </inertial>
        <visual>
            <origin rpy="0 0 0" xyz="0 0 0" />
            <geometry>
                <mesh filename="package://fullbot/meshes/link5_up.STL" />
            </geometry>
            <material name="">
                <color rgba="0.792156862745098 0.819607843137255 0.933333333333333 1" />
            </material>
        </visual>
        <collision>
            <origin rpy="0 0 0" xyz="0 0 0" />
            <geometry>
                <mesh filename="package://fullbot/meshes/link5_up.STL" />
            </geometry>
        </collision>
    </link>
    <joint name="joint5_up" type="revolute">
        <origin rpy="-1.5708 0 -1.5708" xyz="0.014748 -0.00043612 0.183" />
        <parent link="link4_up" />
        <child link="link5_up" />
        <axis xyz="0 0 -1" />
        <limit effort="20" lower="-1.69" upper="3.14" velocity="1.5" />
    </joint>
    <link name="link6_up">
        <inertial>
            <origin rpy="0 0 0" xyz="-0.00127764071195329 7.89251108912481E-09 0.0348924628163476" />
            <mass value="0.240703496519078" />
            <inertia ixx="0.000111819933042724" ixy="1.06441768274538E-12" ixz="3.17569406177314E-07" iyy="0.000124185578330655" iyz="-2.44652552338508E-11" izz="0.000199479046718238" />
        </inertial>
        <visual>
            <origin rpy="0 0 0" xyz="0 0 0" />
            <geometry>
                <mesh filename="package://fullbot/meshes/link6_up.STL" />
            </geometry>
            <material name="">
                <color rgba="0.752941176470588 0.752941176470588 0.752941176470588 1" />
            </material>
        </visual>
        <collision>
            <origin rpy="0 0 0" xyz="0 0 0" />
            <geometry>
                <mesh filename="package://fullbot/meshes/link6_up.STL" />
            </geometry>
        </collision>
    </link>
    <joint name="joint6_up" type="revolute">
        <origin rpy="1.5708 1.5708 0" xyz="0.075873 -0.058524 -0.014339" />
        <parent link="link5_up" />
        <child link="link6_up" />
        <axis xyz="0 0 1" />
        <limit effort="20" lower="-6.28" upper="6.28" velocity="1.5" />
    </joint>
    <link name="link0_right">
        <inertial>
            <origin rpy="0 0 0" xyz="0.00152352214909268 -9.20950558262901E-05 0.0721709833940649" />
            <mass value="1.15012354839417" />
            <inertia ixx="0.00305297729491234" ixy="7.49727624531085E-06" ixz="7.8811653611199E-05" iyy="0.00315399502526908" iyz="-4.77312392810153E-06" izz="0.00149595458411752" />
        </inertial>
        <visual>
            <origin rpy="0 0 0" xyz="0 0 0" />
            <geometry>
                <mesh filename="package://fullbot/meshes/link0_right.STL" />
            </geometry>
            <material name="">
                <color rgba="0.792156862745098 0.819607843137255 0.933333333333333 1" />
            </material>
        </visual>
        <collision>
            <origin rpy="0 0 0" xyz="0 0 0" />
            <geometry>
                <mesh filename="package://fullbot/meshes/link0_right.STL" />
            </geometry>
        </collision>
    </link>
    <joint name="joint0_right" type="fixed">
        <origin rpy="3.14159265358979 -1.04719755119661 1.5707963267949" xyz="0 0.262500000000021 0.808253175473089" />
        <parent link="base_link" />
        <child link="link0_right" />
        <axis xyz="0 0 0" />
    </joint>
    <link name="link1_right">
        <inertial>
            <origin rpy="0 0 0" xyz="-0.00635141038711484 0.000207534921337451 0.0933560223181532" />
            <mass value="1.32562534805268" />
            <inertia ixx="0.0033751569034854" ixy="2.90184699872975E-06" ixz="0.000390274835452127" iyy="0.00397076269428928" iyz="-7.74687080996628E-06" izz="0.00211702052844463" />
        </inertial>
        <visual>
            <origin rpy="0 0 0" xyz="0 0 0" />
            <geometry>
                <mesh filename="package://fullbot/meshes/link1_right.STL" />
            </geometry>
            <material name="">
                <color rgba="0.792156862745098 0.819607843137255 0.933333333333333 1" />
            </material>
        </visual>
        <collision>
            <origin rpy="0 0 0" xyz="0 0 0" />
            <geometry>
                <mesh filename="package://fullbot/meshes/link1_right.STL" />
            </geometry>
        </collision>
    </link>
    <joint name="joint1_right" type="revolute">
        <origin rpy="0 0 0" xyz="0 0 0.1448" />
        <parent link="link0_right" />
        <child link="link1_right" />
        <axis xyz="0 0 1" />
        <limit effort="20" lower="-6.28" upper="6.28" velocity="1.5" />
    </joint>
    <link name="link2_right">
        <inertial>
            <origin rpy="0 0 0" xyz="-0.164337985161048 -0.0131393685703512 -0.0386544729786384" />
            <mass value="2.69362838096021" />
            <inertia ixx="0.00426335070454304" ixy="-0.00277555236003664" ixz="-0.000798532633310513" iyy="0.0150051670245593" iyz="0.000100373269271408" izz="0.0156058685529561" />
        </inertial>
        <visual>
            <origin rpy="0 0 0" xyz="0 0 0" />
            <geometry>
                <mesh filename="package://fullbot/meshes/link2_right.STL" />
            </geometry>
            <material name="">
                <color rgba="0.792156862745098 0.819607843137255 0.933333333333333 1" />
            </material>
        </visual>
        <collision>
            <origin rpy="0 0 0" xyz="0 0 0" />
            <geometry>
                <mesh filename="package://fullbot/meshes/link2_right.STL" />
            </geometry>
        </collision>
    </link>
    <joint name="joint2_right" type="revolute">
        <origin rpy="3.1416 1.5708 0" xyz="-0.065295 0.00034902 0.122" />
        <parent link="link1_right" />
        <child link="link2_right" />
        <axis xyz="0 0 1" />
        <limit effort="20" lower="-2.05" upper="2.09" velocity="1.5" />
    </joint>
    <link name="link3_right">
        <inertial>
            <origin rpy="0 0 0" xyz="0.0790018467474999 -0.0622013835327156 -0.0189188081086681" />
            <mass value="1.30253291173427" />
            <inertia ixx="0.00393746472517653" ixy="0.00136509457478538" ixz="0.00159605824936344" iyy="0.00525341640271265" iyz="-0.000920517395001331" izz="0.00455360703799699" />
        </inertial>
        <visual>
            <origin rpy="0 0 0" xyz="0 0 0" />
            <geometry>
                <mesh filename="package://fullbot/meshes/link3_right.STL" />
            </geometry>
            <material name="">
                <color rgba="0.792156862745098 0.819607843137255 0.933333333333333 1" />
            </material>
        </visual>
        <collision>
            <origin rpy="0 0 0" xyz="0 0 0" />
            <geometry>
                <mesh filename="package://fullbot/meshes/link3_right.STL" />
            </geometry>
        </collision>
    </link>
    <joint name="joint3_right" type="revolute">
        <origin rpy="0 0 0" xyz="-0.2859 -0.053313 -0.0083026" />
        <parent link="link2_right" />
        <child link="link3_right" />
        <axis xyz="0 0 1" />
        <limit effort="20" lower="-3.92" upper="0.19" velocity="1.5" />
    </joint>
    <link name="link4_right">
        <inertial>
            <origin rpy="0 0 0" xyz="0.0321808159995989 -0.000259192543237335 0.107627165980801" />
            <mass value="0.78956108124552" />
            <inertia ixx="0.00404951021883878" ixy="-3.3674543336446E-06" ixz="-0.000990810460485379" iyy="0.00449575360734708" iyz="-2.29158571071361E-06" izz="0.00105176344238809" />
        </inertial>
        <visual>
            <origin rpy="0 0 0" xyz="0 0 0" />
            <geometry>
                <mesh filename="package://fullbot/meshes/link4_right.STL" />
            </geometry>
            <material name="">
                <color rgba="0.792156862745098 0.819607843137255 0.933333333333333 1" />
            </material>
        </visual>
        <collision>
            <origin rpy="0 0 0" xyz="0 0 0" />
            <geometry>
                <mesh filename="package://fullbot/meshes/link4_right.STL" />
            </geometry>
        </collision>
    </link>
    <joint name="joint4_right" type="revolute">
        <origin rpy="0 1.5708 0" xyz="0.15917 -0.077751 -0.057495" />
        <parent link="link3_right" />
        <child link="link4_right" />
        <axis xyz="0 0 1" />
        <limit effort="20" lower="-6.28" upper="6.28" velocity="1.5" />
    </joint>
    <link name="link5_right">
        <inertial>
            <origin rpy="0 0 0" xyz="0.0467464712720566 -0.00940636520692905 -0.0231013135933531" />
            <mass value="0.723053236781345" />
            <inertia ixx="0.000793029275563745" ixy="0.00019796746165297" ixz="-0.000254450161449136" iyy="0.00148592048173132" iyz="5.97839010606921E-05" izz="0.00164706260101592" />
        </inertial>
        <visual>
            <origin rpy="0 0 0" xyz="0 0 0" />
            <geometry>
                <mesh filename="package://fullbot/meshes/link5_right.STL" />
            </geometry>
            <material name="">
                <color rgba="0.792156862745098 0.819607843137255 0.933333333333333 1" />
            </material>
        </visual>
        <collision>
            <origin rpy="0 0 0" xyz="0 0 0" />
            <geometry>
                <mesh filename="package://fullbot/meshes/link5_right.STL" />
            </geometry>
        </collision>
    </link>
    <joint name="joint5_right" type="revolute">
        <origin rpy="-1.5708 0 -1.5708" xyz="0.014748 -0.00043612 0.183" />
        <parent link="link4_right" />
        <child link="link5_right" />
        <axis xyz="0 0 -1" />
        <limit effort="20" lower="-1.69" upper="3.14" velocity="1.5" />
    </joint>
    <link name="link6_right">
        <inertial>
            <origin rpy="0 0 0" xyz="-0.00127764709875855 8.16060202746272E-09 0.0348924616310335" />
            <mass value="0.240703470193428" />
            <inertia ixx="0.000111819928166232" ixy="-8.5304557524986E-12" ixz="3.17582815697291E-07" iyy="0.000124185592316452" iyz="-2.14504240040412E-11" izz="0.000199479022123197" />
        </inertial>
        <visual>
            <origin rpy="0 0 0" xyz="0 0 0" />
            <geometry>
                <mesh filename="package://fullbot/meshes/link6_right.STL" />
            </geometry>
            <material name="">
                <color rgba="0.752941176470588 0.752941176470588 0.752941176470588 1" />
            </material>
        </visual>
        <collision>
            <origin rpy="0 0 0" xyz="0 0 0" />
            <geometry>
                <mesh filename="package://fullbot/meshes/link6_right.STL" />
            </geometry>
        </collision>
    </link>
    <joint name="joint6_right" type="revolute">
        <origin rpy="1.5708 1.5708 0" xyz="0.075873 -0.058524 -0.014339" />
        <parent link="link5_right" />
        <child link="link6_right" />
        <axis xyz="0 0 1" />
        <limit effort="20" lower="-6.28" upper="6.28" velocity="1.5" />
    </joint>
    <link name="link0_left">
        <inertial>
            <origin rpy="0 0 0" xyz="-0.00152352228347186 9.20948264806331E-05 0.0721709830015318" />
            <mass value="1.15012353923379" />
            <inertia ixx="0.00305297726264137" ixy="7.49728091574788E-06" ixz="-7.88116451994899E-05" iyy="0.00315399499788005" iyz="4.77313793260606E-06" izz="0.00149595457246201" />
        </inertial>
        <visual>
            <origin rpy="0 0 0" xyz="0 0 0" />
            <geometry>
                <mesh filename="package://fullbot/meshes/link0_left.STL" />
            </geometry>
            <material name="">
                <color rgba="0.792156862745098 0.819607843137255 0.933333333333333 1" />
            </material>
        </visual>
        <collision>
            <origin rpy="0 0 0" xyz="0 0 0" />
            <geometry>
                <mesh filename="package://fullbot/meshes/link0_left.STL" />
            </geometry>
        </collision>
    </link>
    <joint name="joint0_left" type="fixed">
        <origin rpy="3.14159265358979 1.04719755119659 1.57079632679489" xyz="0 -0.262500000000018 0.808253175473086" />
        <parent link="base_link" />
        <child link="link0_left" />
        <axis xyz="0 0 0" />
    </joint>
    <link name="link1_left">
        <inertial>
            <origin rpy="0 0 0" xyz="-0.00635132541827643 0.000207433439637812 0.0933560224157137" />
            <mass value="1.32563223880842" />
            <inertia ixx="0.0033752021374132" ixy="2.88747662063124E-06" ixz="0.000390243275931501" iyy="0.00397075692793722" iyz="-7.76736476127417E-06" izz="0.0021170422993842" />
        </inertial>
        <visual>
            <origin rpy="0 0 0" xyz="0 0 0" />
            <geometry>
                <mesh filename="package://fullbot/meshes/link1_left.STL" />
            </geometry>
            <material name="">
                <color rgba="0.792156862745098 0.819607843137255 0.933333333333333 1" />
            </material>
        </visual>
        <collision>
            <origin rpy="0 0 0" xyz="0 0 0" />
            <geometry>
                <mesh filename="package://fullbot/meshes/link1_left.STL" />
            </geometry>
        </collision>
    </link>
    <joint name="joint1_left" type="revolute">
        <origin rpy="0 0 0" xyz="0 0 0.1448" />
        <parent link="link0_left" />
        <child link="link1_left" />
        <axis xyz="0 0 1" />
        <limit effort="20" lower="-6.28" upper="6.28" velocity="1.5" />
    </joint>
    <link name="link2_left">
        <inertial>
            <origin rpy="0 0 0" xyz="-0.164335653200961 -0.0131391438496397 -0.0386534541310815" />
            <mass value="2.693519969393" />
            <inertia ixx="0.00426316968491273" ixy="-0.00277539275843287" ixz="-0.000798412755260659" iyy="0.015004913484326" iyz="0.000100414305662904" izz="0.0156055322063192" />
        </inertial>
        <visual>
            <origin rpy="0 0 0" xyz="0 0 0" />
            <geometry>
                <mesh filename="package://fullbot/meshes/link2_left.STL" />
            </geometry>
            <material name="">
                <color rgba="0.792156862745098 0.819607843137255 0.933333333333333 1" />
            </material>
        </visual>
        <collision>
            <origin rpy="0 0 0" xyz="0 0 0" />
            <geometry>
                <mesh filename="package://fullbot/meshes/link2_left.STL" />
            </geometry>
        </collision>
    </link>
    <joint name="joint2_left" type="revolute">
        <origin rpy="3.1416 1.5708 0" xyz="-0.065295 0.00034902 0.122" />
        <parent link="link1_left" />
        <child link="link2_left" />
        <axis xyz="0 0 1" />
        <limit effort="20" lower="-2.05" upper="2.09" velocity="1.5" />
    </joint>
    <link name="link3_left">
        <inertial>
            <origin rpy="0 0 0" xyz="0.0790016512060432 -0.0622011862834298 -0.0189187307620943" />
            <mass value="1.30253713018814" />
            <inertia ixx="0.00393752557798942" ixy="0.00136512084598024" ixz="0.00159609045475645" iyy="0.00525350026062385" iyz="-0.000920532713824777" izz="0.00455371583746519" />
        </inertial>
        <visual>
            <origin rpy="0 0 0" xyz="0 0 0" />
            <geometry>
                <mesh filename="package://fullbot/meshes/link3_left.STL" />
            </geometry>
            <material name="">
                <color rgba="0.792156862745098 0.819607843137255 0.933333333333333 1" />
            </material>
        </visual>
        <collision>
            <origin rpy="0 0 0" xyz="0 0 0" />
            <geometry>
                <mesh filename="package://fullbot/meshes/link3_left.STL" />
            </geometry>
        </collision>
    </link>
    <joint name="joint3_left" type="revolute">
        <origin rpy="0 0 0" xyz="-0.2859 -0.053313 -0.0083026" />
        <parent link="link2_left" />
        <child link="link3_left" />
        <axis xyz="0 0 1" />
        <limit effort="20" lower="-3.92" upper="0.19" velocity="1.5" />
    </joint>
    <link name="link4_left">
        <inertial>
            <origin rpy="0 0 0" xyz="0.0321813918409148 -0.000259353515606797 0.107627755673519" />
            <mass value="0.789550324066767" />
            <inertia ixx="0.00404948831293703" ixy="-3.37071367934127E-06" ixz="-0.000990801773245661" iyy="0.00449572527498313" iyz="-2.29509968742282E-06" izz="0.00105175433912365" />
        </inertial>
        <visual>
            <origin rpy="0 0 0" xyz="0 0 0" />
            <geometry>
                <mesh filename="package://fullbot/meshes/link4_left.STL" />
            </geometry>
            <material name="">
                <color rgba="0.792156862745098 0.819607843137255 0.933333333333333 1" />
            </material>
        </visual>
        <collision>
            <origin rpy="0 0 0" xyz="0 0 0" />
            <geometry>
                <mesh filename="package://fullbot/meshes/link4_left.STL" />
            </geometry>
        </collision>
    </link>
    <joint name="joint4_left" type="revolute">
        <origin rpy="0 1.5708 0" xyz="0.15917 -0.077751 -0.057495" />
        <parent link="link3_left" />
        <child link="link4_left" />
        <axis xyz="0 0 1" />
        <limit effort="20" lower="-6.28" upper="6.28" velocity="1.5" />
    </joint>
    <link name="link5_left">
        <inertial>
            <origin rpy="0 0 0" xyz="0.0467460587567171 -0.0094063461555137 -0.0231014499120238" />
            <mass value="0.723052791881536" />
            <inertia ixx="0.000793040035769921" ixy="0.000197992610855098" ixz="-0.000254454983145896" iyy="0.00148594871876037" iyz="5.97820535578688E-05" izz="0.00164710089968391" />
        </inertial>
        <visual>
            <origin rpy="0 0 0" xyz="0 0 0" />
            <geometry>
                <mesh filename="package://fullbot/meshes/link5_left.STL" />
            </geometry>
            <material name="">
                <color rgba="0.792156862745098 0.819607843137255 0.933333333333333 1" />
            </material>
        </visual>
        <collision>
            <origin rpy="0 0 0" xyz="0 0 0" />
            <geometry>
                <mesh filename="package://fullbot/meshes/link5_left.STL" />
            </geometry>
        </collision>
    </link>
    <joint name="joint5_left" type="revolute">
        <origin rpy="-1.5708 0 -1.5708" xyz="0.014748 -0.00043612 0.183" />
        <parent link="link4_left" />
        <child link="link5_left" />
        <axis xyz="0 0 -1" />
        <limit effort="20" lower="-1.69" upper="3.14" velocity="1.5" />
    </joint>
    <link name="link6_left">
        <inertial>
            <origin rpy="0 0 0" xyz="-0.00127763577348217 7.93220825134888E-09 0.0348924624099836" />
            <mass value="0.24070347329952" />
            <inertia ixx="0.000111819940943311" ixy="-1.15110725036355E-11" ixz="3.17554848775727E-07" iyy="0.0001241855941227" iyz="-3.87077223997555E-11" izz="0.00019947903857224" />
        </inertial>
        <visual>
            <origin rpy="0 0 0" xyz="0 0 0" />
            <geometry>
                <mesh filename="package://fullbot/meshes/link6_left.STL" />
            </geometry>
            <material name="">
                <color rgba="0.752941176470588 0.752941176470588 0.752941176470588 1" />
            </material>
        </visual>
        <collision>
            <origin rpy="0 0 0" xyz="0 0 0" />
            <geometry>
                <mesh filename="package://fullbot/meshes/link6_left.STL" />
            </geometry>
        </collision>
    </link>
    <joint name="joint6_left" type="revolute">
        <origin rpy="1.5708 1.5708 0" xyz="0.075873 -0.058524 -0.014339" />
        <parent link="link5_left" />
        <child link="link6_left" />
        <axis xyz="0 0 1" />
        <limit effort="20" lower="-6.28" upper="6.28" velocity="1.5" />
    </joint>
    
    <transmission name="trans1_up">
        <type>transmission_interface/SimpleTransmission</type>
        <joint name="joint1_up">
            <hardwareInterface>hardware_interface/PositionJointInterface</hardwareInterface>
        </joint>
        <actuator name="motor1_up">
            <hardwareInterface>hardware_interface/PositionJointInterface</hardwareInterface>
            <mechanicalReduction>1</mechanicalReduction>
        </actuator>
    </transmission>
    <transmission name="trans2_up">
        <type>transmission_interface/SimpleTransmission</type>
        <joint name="joint2_up">
            <hardwareInterface>hardware_interface/PositionJointInterface</hardwareInterface>
        </joint>
        <actuator name="motor2_up">
            <hardwareInterface>hardware_interface/PositionJointInterface</hardwareInterface>
            <mechanicalReduction>1</mechanicalReduction>
        </actuator>
    </transmission>
    <transmission name="trans3_up">
        <type>transmission_interface/SimpleTransmission</type>
        <joint name="joint3_up">
            <hardwareInterface>hardware_interface/PositionJointInterface</hardwareInterface>
        </joint>
        <actuator name="motor3_up">
            <hardwareInterface>hardware_interface/PositionJointInterface</hardwareInterface>
            <mechanicalReduction>1</mechanicalReduction>
        </actuator>
    </transmission>
    <transmission name="trans4_up">
        <type>transmission_interface/SimpleTransmission</type>
        <joint name="joint4_up">
            <hardwareInterface>hardware_interface/PositionJointInterface</hardwareInterface>
        </joint>
        <actuator name="motor4_up">
            <hardwareInterface>hardware_interface/PositionJointInterface</hardwareInterface>
            <mechanicalReduction>1</mechanicalReduction>
        </actuator>
    </transmission>
    <transmission name="trans5_up">
        <type>transmission_interface/SimpleTransmission</type>
        <joint name="joint5_up">
            <hardwareInterface>hardware_interface/PositionJointInterface</hardwareInterface>
        </joint>
        <actuator name="motor5_up">
            <hardwareInterface>hardware_interface/PositionJointInterface</hardwareInterface>
            <mechanicalReduction>1</mechanicalReduction>
        </actuator>
    </transmission>
    <transmission name="trans6_up">
        <type>transmission_interface/SimpleTransmission</type>
        <joint name="joint6_up">
            <hardwareInterface>hardware_interface/PositionJointInterface</hardwareInterface>
        </joint>
        <actuator name="motor6_up">
            <hardwareInterface>hardware_interface/PositionJointInterface</hardwareInterface>
            <mechanicalReduction>1</mechanicalReduction>
        </actuator>
    </transmission>
    <!-- Used for fixing robot to Gazebo 'base_link' -->
    <transmission name="trans1_left">
        <type>transmission_interface/SimpleTransmission</type>
        <joint name="joint1_left">
            <hardwareInterface>hardware_interface/PositionJointInterface</hardwareInterface>
        </joint>
        <actuator name="motor1_left">
            <hardwareInterface>hardware_interface/PositionJointInterface</hardwareInterface>
            <mechanicalReduction>1</mechanicalReduction>
        </actuator>
    </transmission>
    <transmission name="trans2_left">
        <type>transmission_interface/SimpleTransmission</type>
        <joint name="joint2_left">
            <hardwareInterface>hardware_interface/PositionJointInterface</hardwareInterface>
        </joint>
        <actuator name="motor2_left">
            <hardwareInterface>hardware_interface/PositionJointInterface</hardwareInterface>
            <mechanicalReduction>1</mechanicalReduction>
        </actuator>
    </transmission>
    <transmission name="trans3_left">
        <type>transmission_interface/SimpleTransmission</type>
        <joint name="joint3_left">
            <hardwareInterface>hardware_interface/PositionJointInterface</hardwareInterface>
        </joint>
        <actuator name="motor3_left">
            <hardwareInterface>hardware_interface/PositionJointInterface</hardwareInterface>
            <mechanicalReduction>1</mechanicalReduction>
        </actuator>
    </transmission>
    <transmission name="trans4_left">
        <type>transmission_interface/SimpleTransmission</type>
        <joint name="joint4_left">
            <hardwareInterface>hardware_interface/PositionJointInterface</hardwareInterface>
        </joint>
        <actuator name="motor4_left">
            <hardwareInterface>hardware_interface/PositionJointInterface</hardwareInterface>
            <mechanicalReduction>1</mechanicalReduction>
        </actuator>
    </transmission>
    <transmission name="trans5_left">
        <type>transmission_interface/SimpleTransmission</type>
        <joint name="joint5_left">
            <hardwareInterface>hardware_interface/PositionJointInterface</hardwareInterface>
        </joint>
        <actuator name="motor5_left">
            <hardwareInterface>hardware_interface/PositionJointInterface</hardwareInterface>
            <mechanicalReduction>1</mechanicalReduction>
        </actuator>
    </transmission>
    <transmission name="trans6_left">
        <type>transmission_interface/SimpleTransmission</type>
        <joint name="joint6_left">
            <hardwareInterface>hardware_interface/PositionJointInterface</hardwareInterface>
        </joint>
        <actuator name="motor6_left">
            <hardwareInterface>hardware_interface/PositionJointInterface</hardwareInterface>
            <mechanicalReduction>1</mechanicalReduction>
        </actuator>
    </transmission>
    <transmission name="trans1_right">
        <type>transmission_interface/SimpleTransmission</type>
        <joint name="joint1_right">
            <hardwareInterface>hardware_interface/PositionJointInterface</hardwareInterface>
        </joint>
        <actuator name="motor1_right">
            <hardwareInterface>hardware_interface/PositionJointInterface</hardwareInterface>
            <mechanicalReduction>1</mechanicalReduction>
        </actuator>
    </transmission>
    <transmission name="trans2_right">
        <type>transmission_interface/SimpleTransmission</type>
        <joint name="joint2_right">
            <hardwareInterface>hardware_interface/PositionJointInterface</hardwareInterface>
        </joint>
        <actuator name="motor2_right">
            <hardwareInterface>hardware_interface/PositionJointInterface</hardwareInterface>
            <mechanicalReduction>1</mechanicalReduction>
        </actuator>
    </transmission>
    <transmission name="trans3_right">
        <type>transmission_interface/SimpleTransmission</type>
        <joint name="joint3_right">
            <hardwareInterface>hardware_interface/PositionJointInterface</hardwareInterface>
        </joint>
        <actuator name="motor3_right">
            <hardwareInterface>hardware_interface/PositionJointInterface</hardwareInterface>
            <mechanicalReduction>1</mechanicalReduction>
        </actuator>
    </transmission>
    <transmission name="trans4_right">
        <type>transmission_interface/SimpleTransmission</type>
        <joint name="joint4_right">
            <hardwareInterface>hardware_interface/PositionJointInterface</hardwareInterface>
        </joint>
        <actuator name="motor4_right">
            <hardwareInterface>hardware_interface/PositionJointInterface</hardwareInterface>
            <mechanicalReduction>1</mechanicalReduction>
        </actuator>
    </transmission>
    <transmission name="trans5_right">
        <type>transmission_interface/SimpleTransmission</type>
        <joint name="joint5_right">
            <hardwareInterface>hardware_interface/PositionJointInterface</hardwareInterface>
        </joint>
        <actuator name="motor5_right">
            <hardwareInterface>hardware_interface/PositionJointInterface</hardwareInterface>
            <mechanicalReduction>1</mechanicalReduction>
        </actuator>
    </transmission>
    <transmission name="trans6_right">
        <type>transmission_interface/SimpleTransmission</type>
        <joint name="joint6_right">
            <hardwareInterface>hardware_interface/PositionJointInterface</hardwareInterface>
        </joint>
        <actuator name="motor6_right">
            <hardwareInterface>hardware_interface/PositionJointInterface</hardwareInterface>
            <mechanicalReduction>1</mechanicalReduction>
        </actuator>
    </transmission>
</robot>

